Workbook

Sheet Synthèse
A1: Pierre-Bénite — Synthèse projet
B3: Compromis signé 04/05/2026 — Marc Chenut & Antoine Bocquet
B4: Maison ~300 m² limite Saint-Genis-Laval — division en 5 lots (3 T3 + 2 T2) rénovés HG
A6: PLAN A — Location courte durée (LCD)
B7: Revenus NET de charges / mois | C7: ='Plan 1 (5 lots)'!C26
B8: Mensualité prêt | C8: =-'Plan 1 (5 lots)'!C27
B9: CASH FLOW AVANT IMPÔT / mois | C9: =C7+C8
A11: PLAN B — Location longue durée (meublée)
B12: Loyer T2 — 2 lots × 850 €/mois | C12: =Hypothèses!$C$22*Hypothèses!$C$47
B13: Loyer T3 — 3 lots × 1 250 €/mois | C13: =Hypothèses!$C$23*Hypothèses!$C$48
B14: Total loyers / mois | C14: =C12+C13
B15: Charges propriétaire (TF + PNO + entretien) / mois | C15: =-(Hypothèses!$C$42+Hypothèses!$C$24*Hypothèses!$C$43)/12-Hypothèses!$C$40-Hypothèses!$C$41
B16: Mensualité prêt | C16: =-'Plan 1 (5 lots)'!C27
B17: CASH FLOW AVANT IMPÔT / mois | C17: =C14+C15+C16
A19: PLAN C — Revente immédiate post-travaux
B20: Coût total opération (achat + travaux + meubles + frais) | C20: =Hypothèses!$C$11
B21: Valeur revente (300 m² × 4 200 €/m²) | C21: =Hypothèses!$C$53
B22: Prix constaté DVF appartement Saint-Genis-Laval rénové HG : 4 200 €/m²
B23: MARGE (revente − coût) | C23: =C21-C20
B24: soit | C24: =(C21-C20)/C20
A26: Financement
B27: Coût total opération | C27: =Hypothèses!$C$11
B28: Apport | C28: =Hypothèses!$C$14
B29: Emprunt sollicité | C29: =Hypothèses!$C$15
B30: Durée — Taux | C30: =Hypothèses!$C$16&" ans à "&TEXT(Hypothèses!$C$17,"0.0%")
B31: Mensualité | C31: ='Plan 1 (5 lots)'!C27
B32: Différé partiel demandé | C32: =Hypothèses!$C$18&" mois (intérêts seuls)"

Sheet Hypothèses
A1: Hypothèses — BP Pierre-Bénite
A3: Acquisition
B4: Poste | C4: Valeur
B5: Prix d'achat | C5: 350000
B6: Notaire (%) | C6: 0.08
B7: Notaire (€) | C7: =C5*C6
B8: Travaux | C8: 300000
B9: Ameublement | C9: 50000
B10: Frais bancaires | C10: 10000
B11: TOTAL opération | C11: =SUM(C5,C7,C8,C9,C10)
A13: Financement
B14: Apport | C14: 150000
B15: Emprunt | C15: =C11-C14
B16: Durée emprunt (années) | C16: 20
B17: Taux d'intérêt | C17: 0.038
B18: Différé (mois) | C18: 18
A20: Composition & revenus (NET de commissions OTA)
B21: Type | C21: Nb lots | D21: Prix net/nuit
B22: T2 | C22: 2 | D22: 75
B23: T3 | C23: 3 | D23: 115
B24: Total lots | C24: =SUM(C22:C23)
B25: Nuits/mois — T2 | C25: 29
B26: Nuits/mois — T3 | C26: 29
A28: Charges courantes (par lot par mois)
B29: Poste | C29: T2 | D29: T3
B30: Électricité / mois | C30: 70 | D30: 70
B31: Internet & TV / mois | C31: 15 | D31: 15
B32: Logiciel gestion / mois | C32: 30 | D32: 30
B33: Consommables / mois | C33: 30 | D33: 30
B34: Ménage / séjour | C34: 17.5 | D34: 25
B35: Blanchisserie / séjour | C35: 15 | D35: 18.5
B36: Nuits / séjour (occupation) | C36: 1.8 | D36: 3
A38: Charges fixes (totales, mensuelles ou annuelles)
B39: Eau / mois (total) | C39: 30
B40: Entretien extérieur / mois | C40: 50
B41: Entretien mobilier / mois | C41: 300
B42: Taxe foncière / an | C42: 2000
B43: Assurance PNO / lot / an | C43: 150
B44: Comptabilité / an | C44: 0
A46: Plan B — Location longue durée (meublée, Saint-Genis)
...

Sheet Plan 1 (5 lots)
A1: Plan 1 — 5 lots (3 T3 + 2 T2) — Régime plein
A3: Revenus location courte durée (annuels, NET de commissions OTA)
B4: Type | C4: / mois | D4: / an
B5: T2 (2 lots × 75 € × 29 nuits) | C5: =Hypothèses!$C$22*Hypothèses!$D$22*Hypothèses!$C$25 | D5: =C5*12
B6: T3 (3 lots × 115 € × 29 nuits) | C6: =Hypothèses!$C$23*Hypothèses!$D$23*Hypothèses!$C$26 | D6: =C6*12
B7: REVENUS TOTAUX | C7: =SUM(C5:C6) | D7: =SUM(D5:D6)
A9: Charges (totales)
B10: Poste | C10: / mois | D10: / an
B11: Électricité | C11: =Hypothèses!$C$22*Hypothèses!$C$30+Hypothèses!$C$23*Hypothèses!$D$30 | D11: =C11*12
B12: Internet & TV | C12: =Hypothèses!$C$22*Hypothèses!$C$31+Hypothèses!$C$23*Hypothèses!$D$31 | D12: =C12*12
B13: Logiciel gestion | C13: =Hypothèses!$C$22*Hypothèses!$C$32+Hypothèses!$C$23*Hypothèses!$D$32 | D13: =C13*12
B14: Consommables | C14: =Hypothèses!$C$22*Hypothèses!$C$33+Hypothèses!$C$23*Hypothèses!$D$33 | D14: =C14*12
B15: Eau | C15: =Hypothèses!$C$39 | D15: =C15*12
B16: Entretien extérieur | C16: =Hypothèses!$C$40 | D16: =C16*12
B17: Entretien mobilier | C17: =Hypothèses!$C$41 | D17: =C17*12
B18: Ménage + blanchisserie T2 | C18: =Hypothèses!$C$22*(Hypothèses!$C$25/Hypothèses!$C$36)*(Hypothèses!$C$34+Hypothèses!$C$35) | D18: =C18*12
B19: Ménage + blanchisserie T3 | C19: =Hypothèses!$C$23*(Hypothèses!$C$26/Hypothèses!$D$36)*(Hypothèses!$D$34+Hypothèses!$D$35) | D19: =C19*12
B20: Taxe foncière (annuelle) | C20: =Hypothèses!$C$42/12 | D20: =Hypothèses!$C$42
B21: Assurance PNO (par lot) | C21: =Hypothèses!$C$24*Hypothèses!$C$43/12 | D21: =Hypothèses!$C$24*Hypothèses!$C$43
B22: Comptabilité | C22: =Hypothèses!$C$44/12 | D22: =Hypothèses!$C$44
B23: CHARGES TOTALES | C23: =SUM(C11:C22) | D23: =SUM(D11:D22)
A25: Résultat opérationnel
B26: Revenus NET de charges | C26: =C7-C23 | D26: =D7-D23
B27: Mensualité prêt (capital + intérêts) | C27: =-PMT(Hypothèses!$C$17/12, Hypothèses!$C$16*12, Hypothèses!$C$15) | D27: =C27*12
B28: CASH FLOW AVANT IMPÔT | C28: =C26-C27 | D28: =D26-D27

Sheet Projection 3 ans
A1: Projection 3 ans — Phase travaux + Montée + Régime plein
B3: Hypothèses : Acte M0 → Travaux M1-M6 (revenus=0) → Montée M7-M9 (50/75/90 %) → Plein M10+
B4: Différé partiel 18 mois (intérêts seuls jusqu'à M+18). An 1 = 12 mois intérêts seuls. An 2 = 6 mois intérêts seuls + 6 mois mensualité pleine. An 3 = 12 mois mensualité pleine.
B6: Poste | C6: An 1 | D6: An 2 | E6: An 3
B7: Revenus location courte durée | C7: ='Plan 1 (5 lots)'!D7*0.4291666666666667 | D7: ='Plan 1 (5 lots)'!D7 | E7: ='Plan 1 (5 lots)'!D7
B8: − Charges totales | C8: =-'Plan 1 (5 lots)'!D23*0.4291666666666667 | D8: =-'Plan 1 (5 lots)'!D23 | E8: =-'Plan 1 (5 lots)'!D23
B9: =Revenus NET de charges | C9: =C7+C8 | D9: =D7+D8 | E9: =E7+E8
B11: − Annuité prêt (différé sur an 1-2) | C11: =-Hypothèses!$C$15*Hypothèses!$C$17 | D11: =-Hypothèses!$C$15*Hypothèses!$C$17*0.5-('Plan 1 (5 lots)'!C27)*6 | E11: =-('Plan 1 (5 lots)'!C27)*12
B13: =CASH FLOW AVANT IMPÔT | C13: =C9+C11 | D13: =D9+D11 | E13: =E9+E11
B14: Cash flow / mois moyen | C14: =C13/12 | D14: =D13/12 | E14: =E13/12
B16: Cash flow CUMULÉ (depuis acte) | C16: =C13 | D16: =C16+D13 | E16: =D16+E13

Sheet Amortissement
A1: Amortissement annuel emprunt
B3: Mensualité | C3: =-PMT(Hypothèses!$C$17/12, Hypothèses!$C$16*12, Hypothèses!$C$15)
B5: Année | C5: Capital début | D5: Annuité (× 12) | E5: Intérêts an | F5: Capital remboursé
B6: 1 | C6: =Hypothèses!$C$15 | D6: =$C$3*12 | E6: =D6-F6 | F6: =C6-(Hypothèses!$C$15)*((1+Hypothèses!$C$17/12)^(Hypothèses!$C$16*12)-(1+Hypothèses!$C$17/12)^(1*12))/((1+Hypothèses!$C$17/12)^(Hypothèses!$C$16*12)-1)
B7: 2 | C7: =C6-F6 | D7: =$C$3*12 | E7: =D7-F7 | F7: =C7-(Hypothèses!$C$15)*((1+Hypothèses!$C$17/12)^(Hypothèses!$C$16*12)-(1+Hypothèses!$C$17/12)^(2*12))/((1+Hypothèses!$C$17/12)^(Hypothèses!$C$16*12)-1)
B8: 3 | C8: =C7-F7 | D8: =$C$3*12 | E8: =D8-F8 | F8: =C8-(Hypothèses!$C$15)*((1+Hypothèses!$C$17/12)^(Hypothèses!$C$16*12)-(1+Hypothèses!$C$17/12)^(3*12))/((1+Hypothèses!$C$17/12)^(Hypothèses!$C$16*12)-1)
B9: 4 | C9: =C8-F8 | D9: =$C$3*12 | E9: =D9-F9 | F9: =C9-(Hypothèses!$C$15)*((1+Hypothèses!$C$17/12)^(Hypothèses!$C$16*12)-(1+Hypothèses!$C$17/12)^(4*12))/((1+Hypothèses!$C$17/12)^(Hypothèses!$C$16*12)-1)
B10: 5 | C10: =C9-F9 | D10: =$C$3*12 | E10: =D10-F10 | F10: =C10-(Hypothèses!$C$15)*((1+Hypothèses!$C$17/12)^(Hypothèses!$C$16*12)-(1+Hypothèses!$C$17/12)^(5*12))/((1+Hypothèses!$C$17/12)^(Hypothèses!$C$16*12)-1)
B11: 6 | C11: =C10-F10 | D11: =$C$3*12 | E11: =D11-F11 | F11: =C11-(Hypothèses!$C$15)*((1+Hypothèses!$C$17/12)^(Hypothèses!$C$16*12)-(1+Hypothèses!$C$17/12)^(6*12))/((1+Hypothèses!$C$17/12)^(Hypothèses!$C$16*12)-1)
B12: 7 | C12: =C11-F11 | D12: =$C$3*12 | E12: =D12-F12 | F12: =C12-(Hypothèses!$C$15)*((1+Hypothèses!$C$17/12)^(Hypothèses!$C$16*12)-(1+Hypothèses!$C$17/12)^(7*12))/((1+Hypothèses!$C$17/12)^(Hypothèses!$C$16*12)-1)
B13: 8 | C13: =C12-F12 | D13: =$C$3*12 | E13: =D13-F13 | F13: =C13-(Hypothèses!$C$15)*((1+Hypothèses!$C$17/12)^(Hypothèses!$C$16*12)-(1+Hypothèses!$C$17/12)^(8*12))/((1+Hypothèses!$C$17/12)^(Hypothèses!$C$16*12)-1)
B14: 9 | C14: =C13-F13 | D14: =$C$3*12 | E14: =D14-F14 | F14: =C14-(Hypothèses!$C$15)*((1+Hypothèses!$C$17/12)^(Hypothèses!$C$16*12)-(1+Hypothèses!$C$17/12)^(9*12))/((1+Hypothèses!$C$17/12)^(Hypothèses!$C$16*12)-1)
B15: 10 | C15: =C14-F14 | D15: =$C$3*12 | E15: =D15-F15 | F15: =C15-(Hypothèses!$C$15)*((1+Hypothèses!$C$17/12)^(Hypothèses!$C$16*12)-(1+Hypothèses!$C$17/12)^(10*12))/((1+Hypothèses!$C$17/12)^(Hypothèses!$C$16*12)-1)
B16: 11 | C16: =C15-F15 | D16: =$C$3*12 | E16: =D16-F16 | F16: =C16-(Hypothèses!$C$15)*((1+Hypothèses!$C$17/12)^(Hypothèses!$C$16*12)-(1+Hypothèses!$C$17/12)^(11*12))/((1+Hypothèses!$C$17/12)^(Hypothèses!$C$16*12)-1)
B17: 12 | C17: =C16-F16 | D17: =$C$3*12 | E17: =D17-F17 | F17: =C17-(Hypothèses!$C$15)*((1+Hypothèses!$C$17/12)^(Hypothèses!$C$16*12)-(1+Hypothèses!$C$17/12)^(12*12))/((1+Hypothèses!$C$17/12)^(Hypothèses!$C$16*12)-1)
B18: 13 | C18: =C17-F17 | D18: =$C$3*12 | E18: =D18-F18 | F18: =C18-(Hypothèses!$C$15)*((1+Hypothèses!$C$17/12)^(Hypothèses!$C$16*12)-(1+Hypothèses!$C$17/12)^(13*12))/((1+Hypothèses!$C$17/12)^(Hypothèses!$C$16*12)-1)
B19: 14 | C19: =C18-F18 | D19: =$C$3*12 | E19: =D19-F19 | F19: =C19-(Hypothèses!$C$15)*((1+Hypothèses!$C$17/12)^(Hypothèses!$C$16*12)-(1+Hypothèses!$C$17/12)^(14*12))/((1+Hypothèses!$C$17/12)^(Hypothèses!$C$16*12)-1)
B20: 15 | C20: =C19-F19 | D20: =$C$3*12 | E20: =D20-F20 | F20: =C20-(Hypothèses!$C$15)*((1+Hypothèses!$C$17/12)^(Hypothèses!$C$16*12)-(1+Hypothèses!$C$17/12)^(15*12))/((1+Hypothèses!$C$17/12)^(Hypothèses!$C$16*12)-1)
B21: 16 | C21: =C20-F20 | D21: =$C$3*12 | E21: =D21-F21 | F21: =C21-(Hypothèses!$C$15)*((1+Hypothèses!$C$17/12)^(Hypothèses!$C$16*12)-(1+Hypothèses!$C$17/12)^(16*12))/((1+Hypothèses!$C$17/12)^(Hypothèses!$C$16*12)-1)
B22: 17 | C22: =C21-F21 | D22: =$C$3*12 | E22: =D22-F22 | F22: =C22-(Hypothèses!$C$15)*((1+Hypothèses!$C$17/12)^(Hypothèses!$C$16*12)-(1+Hypothèses!$C$17/12)^(17*12))/((1+Hypothèses!$C$17/12)^(Hypothèses!$C$16*12)-1)
B23: 18 | C23: =C22-F22 | D23: =$C$3*12 | E23: =D23-F23 | F23: =C23-(Hypothèses!$C$15)*((1+Hypothèses!$C$17/12)^(Hypothèses!$C$16*12)-(1+Hypothèses!$C$17/12)^(18*12))/((1+Hypothèses!$C$17/12)^(Hypothèses!$C$16*12)-1)
B24: 19 | C24: =C23-F23 | D24: =$C$3*12 | E24: =D24-F24 | F24: =C24-(Hypothèses!$C$15)*((1+Hypothèses!$C$17/12)^(Hypothèses!$C$16*12)-(1+Hypothèses!$C$17/12)^(19*12))/((1+Hypothèses!$C$17/12)^(Hypothèses!$C$16*12)-1)
B25: 20 | C25: =C24-F24 | D25: =$C$3*12 | E25: =D25-F25 | F25: =C25-(Hypothèses!$C$15)*((1+Hypothèses!$C$17/12)^(Hypothèses!$C$16*12)-(1+Hypothèses!$C$17/12)^(20*12))/((1+Hypothèses!$C$17/12)^(Hypothèses!$C$16*12)-1)
B26: TOTAL | D26: =SUM(D6:D25) | E26: =SUM(E6:E25) | F26: =SUM(F6:F25)
